Workbook

Sheet 2015-2016
B2: Temporada 2016/2017 | D2: General | M2: Ataque | U2: Defensa | AA2: Tipo de juego | AF2: Extra cancha
B3: Posición en la tabla | C3: Equipo | D3: Goles a favor | E3: Goles en contra | F3: Diferencia de goles | G3: Porterias en cero | H3: Tarjetas Amarillas | I3: Tarjetas Rojas | J3: XG F | K3: XG A | L3: G vs XG | M3: Tiros | N3: Tiros a gol | O3: Gol de penal | P3: Gol de cabeza | Q3: Gol dentro del área | R3: Gol fuera del área | S3: Gol de contragolpe | T3: Fueras de lugar | U3: Auotgoles | V3: Penales provocados | W3: Paradas | X3: Despejes | Y3: Barridas | Z3: Faltas | AA3: # de pases | AB3: Pases filtrados | AC3: Pases hacia atrás | AD3: Centros | AE3: Corners | AF3: Dinero gastado en transferencias (Millones de euros) | AG3: Dinero ingresado por transferencias (millones de euros) | AH3: Jugadores nuevos | AI3: Jugadores vendidos | AJ3: Valor de la plantilla | AK3: # de jugadores | AL3: Valor promedio jugadores (millones de euros) | AM3: Asistencia promedio al estadio | AN3: % ventaja local | AO3: Competencias Europeas | AP3: Recien ascendido | AQ3: Champions | AR3: Descenso | AS3: Big 6 | AT3: Temporada
B4: 1 | C4: Leicester City | D4: 68 | E4: 36 | F4: 32 | G4: 15 | H4: 48 | I4: 3 | J4: NA | K4: NA | L4: NA | M4: 522 | N4: 179 | O4: 10 | P4: 11 | Q4: 65 | R4: 3 | S4: 6 | T4: 50 | U4: 0 | V4: 4 | W4: 99 | X4: 1040 | Y4: 869 | Z4: 406 | AA4: 13370 | AB4: 54 | AC4: 1970 | AD4: 762 | AE4: 197 | AF4: 49.9 | AG4: 9.45 | AH4: 25 | AI4: 32 | AJ4: 161.1 | AK4: 35 | AL4: 4.6028571 | AM4: 31998 | AN4: 0 | AO4: 0 | AP4: 0 | AQ4: 1 | AR4: 0 | AS4: 0 | AT4: 15/16
B5: 2 | C5: Arsenal | D5: 65 | E5: 36 | F5: 29 | G5: 18 | H5: 40 | I5: 4 | J5: NA | K5: NA | L5: NA | M5: 571 | N5: 211 | O5: 1 | P5: 13 | Q5: 61 | R5: 4 | S5: 3 | T5: 86 | U5: 3 | V5: 1 | W5: 118 | X5: 849 | Y5: 709 | Z5: 348 | AA5: 21249 | AB5: 168 | AC5: 2946 | AD5: 754 | AE5: 227 | AF5: 26.5 | AG5: 2.5 | AH5: 15 | AI5: 12 | AJ5: 457.85 | AK5: 41 | AL5: 11.167073 | AM5: 59944 | AN5: 0.17 | AO5: 1 | AP5: 0 | AQ5: 1 | AR5: 0 | AS5: 1 | AT5: =AT4 -> 15/16
B6: 3 | C6: Tottenham Hotspur | D6: 69 | E6: 35 | F6: 34 | G6: 13 | H6: 72 | I6: 1 | J6: NA | K6: NA | L6: NA | M6: 659 | N6: 252 | O6: 5 | P6: 7 | Q6: 59 | R6: 10 | S6: 3 | T6: 72 | U6: 3 | V6: 2 | W6: 89 | X6: 1046 | Y6: 805 | Z6: 451 | AA6: 18649 | AB6: 64 | AC6: 2708 | AD6: 738 | AE6: 254 | AF6: 71 | AG6: 87.25 | AH6: 11 | AI6: 21 | AJ6: 371.85 | AK6: 31 | AL6: 11.995161 | AM6: 35776 | AN6: 0.08 | AO6: 1 | AP6: 0 | AQ6: 1 | AR6: 0 | AS6: 1 | AT6: =AT5 -> 15/16
B7: 4 | C7: Manchester City | D7: 71 | E7: 41 | F7: 30 | G7: 16 | H7: 61 | I7: 1 | J7: NA | K7: NA | L7: NA | M7: 615 | N7: 210 | O7: 5 | P7: 13 | Q7: 57 | R7: 14 | S7: 5 | T7: 63 | U7: 1 | V7: 1 | W7: 86 | X7: 940 | Y7: 729 | Z7: 409 | AA7: 20488 | AB7: 84 | AC7: 2895 | AD7: 866 | AE7: 257 | AF7: 208.47 | AG7: 67.44 | AH7: 22 | AI7: 25 | AJ7: 499.35 | AK7: 38 | AL7: 13.140789 | AM7: 54041 | AN7: 0.15 | AO7: 1 | AP7: 0 | AQ7: 1 | AR7: 0 | AS7: 1 | AT7: =AT6 -> 15/16
B8: 5 | C8: Manchester United | D8: 49 | E8: 35 | F8: 14 | G8: 18 | H8: 65 | I8: 1 | J8: NA | K8: NA | L8: NA | M8: 430 | N8: 144 | O8: 3 | P8: 5 | Q8: 44 | R8: 5 | S8: 2 | T8: 75 | U8: 2 | V8: 2 | W8: 90 | X8: 755 | Y8: 760 | Z8: 473 | AA8: 20070 | AB8: 43 | AC8: 3221 | AD8: 786 | AE8: 228 | AF8: 156 | AG8: 100.67 | AH8: 22 | AI8: 20 | AJ8: 439.85 | AK8: 44 | AL8: 9.9965909 | AM8: 75286 | AN8: 0.3 | AO8: 1 | AP8: 0 | AQ8: 0 | AR8: 0 | AS8: 1 | AT8: =AT7 -> 15/16
B9: 6 | C9: Southampton | D9: 59 | E9: 41 | F9: 18 | G9: 12 | H9: 57 | I9: 6 | J9: NA | K9: NA | L9: NA | M9: 519 | N9: 166 | O9: 3 | P9: 15 | Q9: 53 | R9: 6 | S9: 3 | T9: 98 | U9: 0 | V9: 1 | W9: 94 | X9: 1101 | Y9: 714 | Z9: 417 | AA9: 15913 | AB9: 46 | AC9: 2358 | AD9: 956 | AE9: 220 | AF9: 60.1 | AG9: 52.7 | AH9: 16 | AI9: 17 | AJ9: 225.5 | AK9: 35 | AL9: 6.4428571 | AM9: 30751 | AN9: 0.13 | AO9: 1 | AP9: 0 | AQ9: 0 | AR9: 0 | AS9: 0 | AT9: =AT8 -> 15/16
B10: 7 | C10: West Ham United | D10: 65 | E10: 51 | F10: 14 | G10: 11 | H10: 58 | I10: 5 | J10: NA | K10: NA | L10: NA | M10: 558 | N10: 185 | O10: 4 | P10: 15 | Q10: 55 | R10: 10 | S10: 2 | T10: 82 | U10: 2 | V10: 8 | W10: 111 | X10: 1003 | Y10: 711 | Z10: 381 | AA10: 15031 | AB10: 32 | AC10: 2236 | AD10: 805 | AE10: 224 | AF10: 52.7 | AG10: 18.52 | AH10: 25 | AI10: 26 | AJ10: 201.33 | AK10: 50 | AL10: 4.0266 | AM10: 34910 | AN10: 0.02 | AO10: 1 | AP10: 0 | AQ10: 0 | AR10: 0 | AS10: 0 | AT10: =AT9 -> 15/16
B11: 8 | C11: Liverpool | D11: 63 | E11: 50 | F11: 13 | G11: 11 | H11: 61 | I11: 3 | J11: NA | K11: NA | L11: NA | M11: 629 | N11: 202 | O11: 2 | P11: 12 | Q11: 48 | R11: 15 | S11: 1 | T11: 91 | U11: 1 | V11: 3 | W11: 81 | X11: 871 | Y11: 871 | Z11: 410 | AA11: 19733 | AB11: 75 | AC11: 2846 | AD11: 780 | AE11: 265 | AF11: 126.5 | AG11: 90.55 | AH11: 24 | AI11: 24 | AJ11: 375.25 | AK11: 44 | AL11: 8.5284091 | AM11: 43910 | AN11: 0.09 | AO11: 1 | AP11: 0 | AQ11: 0 | AR11: 0 | AS11: 1 | AT11: =AT10 -> 15/16
B12: 9 | C12: Stoke City | D12: 41 | E12: 55 | F12: -14 | G12: 10 | H12: 51 | I12: 4 | J12: NA | K12: NA | L12: NA | M12: 419 | N12: 128 | O12: 5 | P12: 9 | Q12: 33 | R12: 8 | S12: 0 | T12: 103 | U12: 0 | V12: 5 | W12: 121 | X12: 826 | Y12: 710 | Z12: 420 | AA12: 16342 | AB12: 60 | AC12: 2440 | AD12: 683 | AE12: 153 | AF12: 53.65 | AG12: 23.2 | AH12: 13 | AI12: 14 | AJ12: 147 | AK12: 31 | AL12: 4.7419355 | AM12: 27534 | AN12: 0.1 | AO12: 0 | AP12: 0 | AQ12: 0 | AR12: 0 | AS12: 0 | AT12: =AT11 -> 15/16
B13: 10 | C13: Chelsea | D13: 59 | E13: 53 | F13: 6 | G13: 9 | H13: 58 | I13: 5 | J13: NA | K13: NA | L13: NA | M13: 526 | N13: 173 | O13: 4 | P13: 6 | Q13: 48 | R13: 11 | S13: 1 | T13: 90 | U13: 2 | V13: 4 | W13: 122 | X13: 790 | Y13: 790 | Z13: 401 | AA13: 19664 | AB13: 74 | AC13: 2933 | AD13: 732 | AE13: 240 | AF13: 96.5 | AG13: 87.49 | AH13: 39 | AI13: 37 | AJ13: 553.5 | AK13: 40 | AL13: 13.8375 | AM13: 41500 | AN13: -0.03 | AO13: 1 | AP13: 0 | AQ13: 0 | AR13: 0 | AS13: 1 | AT13: =AT12 -> 15/16
B14: 11 | C14: Everton | D14: 59 | E14: 55 | F14: 4 | G14: 10 | H14: 44 | I14: 5 | J14: NA | K14: NA | L14: NA | M14: 491 | N14: 175 | O14: 4 | P14: 10 | Q14: 53 | R14: 6 | S14: 2 | T14: 55 | U14: 1 | V14: 6 | W14: 127 | X14: 994 | Y14: 730 | Z14: 306 | AA14: 17947 | AB14: 57 | AC14: 2699 | AD14: 782 | AE14: 218 | AF14: 48.2 | AG14: 11 | AH14: 18 | AI14: 17 | AJ14: 249.85 | AK14: 39 | AL14: 6.4064103 | AM14: 38124 | AN14: 0.05 | AO14: 0 | AP14: 0 | AQ14: 0 | AR14: 0 | AS14: 0 | AT14: =AT13 -> 15/16
B15: 12 | C15: Swansea City | D15: 42 | E15: 52 | F15: -10 | G15: 9 | H15: 60 | I15: 1 | J15: NA | K15: NA | L15: NA | M15: 441 | N15: 136 | O15: 5 | P15: 6 | Q15: 35 | R15: 7 | S15: 3 | T15: 82 | U15: 5 | V15: 2 | W15: 119 | X15: 1058 | Y15: 638 | Z15: 392 | AA15: 18169 | AB15: 46 | AC15: 2796 | AD15: 725 | AE15: 163 | AF15: 21.81 | AG15: 16.81 | AH15: 20 | AI15: 24 | AJ15: 145.8 | AK15: 36 | AL15: 4.05 | AM15: 20711 | AN15: 0.09 | AO15: 0 | AP15: 0 | AQ15: 0 | AR15: 0 | AS15: 0 | AT15: =AT14 -> 15/16
B16: 13 | C16: Watford | D16: 40 | E16: 50 | F16: -10 | G16: 11 | H16: 73 | I16: 3 | J16: NA | K16: NA | L16: NA | M16: 446 | N16: 140 | O16: 6 | P16: 5 | Q16: 37 | R16: 3 | S16: 0 | T16: 50 | U16: 2 | V16: 8 | W16: 121 | X16: 931 | Y16: 794 | Z16: 455 | AA16: 14531 | AB16: 29 | AC16: 2164 | AD16: 703 | AE16: 164 | AF16: 82.8 | AG16: 9.75 | AH16: 33 | AI16: 30 | AJ16: 137 | AK16: 39 | AL16: 3.5128205 | AM16: 20594 | AN16: 0.12 | AO16: 0 | AP16: 1 | AQ16: 0 | AR16: 0 | AS16: 0 | AT16: =AT15 -> 15/16
... B23: 20 | C23: Aston Villa | D23: 27 | E23: 76 | F23: -49 | G23: 6 | H23: 75 | I23: 3 | J23: NA | K23: NA | L23: NA | M23: 380 | N23: 110 | O23: 2 | P23: 6 | Q23: 21 | R23: 6 | S23: 1 | T23: 42 | U23: 4 | V23: 5 | W23: 116 | X23: 973 | Y23: 731 | Z23: 429 | AA23: 15308 | AB23: 12 | AC23: 2269 | AD23: 796 | AE23: 167 | AF23: 66.55 | AG23: 64.7 | AH23: 29 | AI23: 32 | AJ23: 117.95 | AK23: 44 | AL23: 2.6806818 | AM23: 33690 | AN23: 0.06 | AO23: 0 | AP23: 0 | AQ23: 0 | AR23: 1 | AS23: 0 | AT23: =AT22 -> 15/16
B26: Fuentes: | C26: https://fbref.com/en/comps/9/shooting/Premier-League-Stats
C27: https://footystats.org/england/premier-league#
C28: https://www.premierleague.com/stats/top/clubs/wins
C29: https://www.transfermarkt.mx/premier-league/einnahmenausgaben/wettbewerb/GB1/plus/0?ids=a&sa=&saison_id=2015&saison_id_bis=2015&nat=&pos=&altersklasse=&w_s=&leihe=&intern=0
C30: https://www.transfermarkt.mx/premier-league/startseite/wettbewerb/GB1/saison_id/2015

Sheet 2016-2017
B2: Temporada 2016/2017 | D2: General | M2: Ataque | U2: Defensa | AA2: Tipo de juego | AF2: Extra cancha
B3: Posición en la tabla | C3: Equipo | D3: Goles a favor | E3: Goles en contra | F3: Diferencia de goles | G3: Porterias en cero | H3: Tarjetas Amarillas | I3: Tarjetas Rojas | J3: XG F | K3: XG A | L3: G vs XG | M3: Tiros | N3: Tiros a gol | O3: Gol de penal | P3: Gol de cabeza | Q3: Gol dentro del área | R3: Gol fuera del área | S3: Gol de contragolpe | T3: Fueras de lugar | U3: Auotgoles | V3: Penales provocados | W3: Paradas | X3: Despejes | Y3: Barridas | Z3: Faltas | AA3: # de pases | AB3: Pases filtrados | AC3: Pases hacia atrás | AD3: Centros | AE3: Corners | AF3: Dinero gastado en transferencias (Millones de euros) | AG3: Dinero ingresado por transferencias (millones de euros) | AH3: Jugadores nuevos | AI3: Jugadores vendidos | AJ3: Valor de la plantilla | AK3: # de jugadores | AL3: Valor promedio jugadores | AM3: Asistencia promedio al estadio | AN3: % ventaja local | AO3: Competencias Europeas | AP3: Recien ascendido | AQ3: Champions | AR3: Descenso | AS3: Big 6 | AT3: Temporada
B4: 1 | C4: Chelsea | D4: 85 | E4: 33 | F4: 52 | G4: 16 | H4: 72 | I4: 0 | J4: NA | K4: NA | L4: NA | M4: 582 | N4: 205 | O4: 2 | P4: 8 | Q4: 73 | S4: 12 | T4: 65 | U4: 1 | V4: 2 | W4: 72 | X4: 839 | Y4: 652 | Z4: 394 | AA4: 20125 | AB4: 103 | AC4: 2967 | AD4: 697 | AE4: 218 | AF4: 132.8 | AG4: 108.9 | AH4: 27 | AI4: 30 | AJ4: 686.7 | AK4: 49 | AL4: =AJ4/AK4 -> 14.014286 | AM4: 41508 | AN4: 0.14 | AO4: 0 | AP4: 0 | AQ4: 1 | AR4: 0 | AS4: 1 | AT4: 16/17
B5: 2 | C5: Tottenham Hotspur | D5: 86 | E5: 26 | F5: 60 | G5: 17 | H5: 62 | I5: 0 | J5: NA | K5: NA | L5: NA | M5: 670 | N5: 257 | O5: 7 | P5: 10 | Q5: 74 | S5: 12 | T5: 74 | U5: 1 | V5: 2 | W5: 84 | X5: 1003 | Y5: 661 | Z5: 431 | AA5: 20153 | AB5: 47 | AC5: 3132 | AD5: 763 | AE5: 273 | AF5: 83.5 | AG5: 52.3 | AH5: 8 | AI5: 8 | AJ5: 543.65 | AK5: 38 | AL5: =AJ5/AK5 -> 14.306579 | AM5: 31639 | AN5: 0.2 | AO5: 1 | AP5: 0 | AQ5: 1 | AR5: 0 | AS5: 1 | AT5: =AT4 -> 16/17
B6: 3 | C6: Manchester City | D6: 80 | E6: 39 | F6: 41 | G6: 12 | H6: 71 | I6: 4 | J6: NA | K6: NA | L6: NA | M6: 633 | N6: 215 | O6: 7 | P6: 8 | Q6: 73 | S6: 7 | T6: 93 | U6: 1 | V6: 5 | W6: 66 | X6: 904 | Y6: 642 | Z6: 395 | AA6: 22705 | AB6: 124 | AC6: 3534 | AD6: 810 | AE6: 280 | AF6: 215 | AG6: 35.35 | AH6: 31 | AI6: 25 | AJ6: 576.6 | AK6: 35 | AL6: =AJ6/AK6 -> 16.474286 | AM6: 54019 | AN6: 0.03 | AO6: 1 | AP6: 0 | AQ6: 1 | AR6: 0 | AS6: 1 | AT6: =AT5 -> 16/17
B7: 4 | C7: Liverpool | D7: 78 | E7: 42 | F7: 36 | G7: 12 | H7: 54 | I7: 0 | J7: NA | K7: NA | L7: NA | M7: 639 | N7: 236 | O7: 7 | P7: 12 | Q7: 65 | S7: 13 | T7: 78 | U7: 0 | V7: 5 | W7: 72 | X7: 883 | Y7: 718 | Z7: 396 | AA7: 22283 | AB7: 58 | AC7: 3292 | AD7: 815 | AE7: 249 | AF7: 79.9 | AG7: 85.38 | AH7: 21 | AI7: 19 | AJ7: 425.65 | AK7: 38 | AL7: =AJ7/AK7 -> 11.201316 | AM7: 53016 | AN7: 0.15 | AO7: 0 | AP7: 0 | AQ7: 1 | AR7: 0 | AS7: 1 | AT7: =AT6 -> 16/17
B8: 5 | C8: Arsenal | D8: 77 | E8: 44 | F8: 33 | G8: 13 | H8: 68 | I8: 3 | J8: NA | K8: NA | L8: NA | M8: 568 | N8: 201 | O8: 4 | P8: 17 | Q8: 70 | S8: 7 | T8: 99 | U8: 1 | V8: 10 | W8: 123 | X8: 839 | Y8: 674 | Z8: 394 | AA8: 21392 | AB8: 129 | AC8: 2835 | AD8: 701 | AE8: 227 | AF8: 113.04 | AG8: 10.35 | AH8: 11 | AI8: 12 | AJ8: 542 | AK8: 42 | AL8: =AJ8/AK8 -> 12.904762 | AM8: 59957 | AN8: 0.15 | AO8: 1 | AP8: 0 | AQ8: 0 | AR8: 0 | AS8: 1 | AT8: =AT7 -> 16/17
B9: 6 | C9: Manchester United | D9: 54 | E9: 29 | F9: 25 | G9: 17 | H9: 78 | I9: 2 | J9: NA | K9: NA | L9: NA | M9: 589 | N9: 207 | O9: 3 | P9: 9 | Q9: 47 | S9: 7 | T9: 102 | U9: 1 | V9: 5 | W9: 87 | X9: 1110 | Y9: 690 | Z9: 498 | AA9: 20247 | AB9: 99 | AC9: 3177 | AD9: 852 | AE9: 217 | AF9: 185 | AG9: 47.25 | AH9: 9 | AI9: 14 | AJ9: 531.45 | AK9: 42 | AL9: =AJ9/AK9 -> 12.653571 | AM9: 75290 | AN9: 0.07 | AO9: 1 | AP9: 0 | AQ9: 0 | AR9: 0 | AS9: 1 | AT9: =AT8 -> 16/17
B10: 7 | C10: Everton | D10: 62 | E10: 44 | F10: 18 | G10: 13 | H10: 72 | I10: 2 | J10: NA | K10: NA | L10: NA | M10: 500 | N10: 192 | O10: 3 | P10: 13 | Q10: 59 | S10: 3 | T10: 83 | U10: 1 | V10: 5 | W10: 104 | X10: 1117 | Y10: 714 | Z10: 457 | AA10: 17584 | AB10: 40 | AC10: 2743 | AD10: 775 | AE10: 196 | AF10: 86 | AG10: 60.8 | AH10: 18 | AI10: 19 | AJ10: 311.25 | AK10: 39 | AL10: =AJ10/AK10 -> 7.9807692 | AM10: 39047 | AN10: 0.32 | AO10: 0 | AP10: 0 | AQ10: 0 | AR10: 0 | AS10: 0 | AT10: =AT9 -> 16/17
B11: 8 | C11: Southampton | D11: 41 | E11: 48 | F11: -7 | G11: 14 | H11: 59 | I11: 2 | J11: NA | K11: NA | L11: NA | M11: 549 | N11: 179 | O11: 3 | P11: 4 | Q11: 37 | S11: 4 | T11: 75 | U11: 0 | V11: 9 | W11: 82 | X11: 919 | Y11: 675 | Z11: 426 | AA11: 18240 | AB11: 58 | AC11: 2784 | AD11: 960 | AE11: 198 | AF11: 68.9 | AG11: 85.05 | AH11: 12 | AI11: 9 | AJ11: 263.75 | AK11: 36 | AL11: =AJ11/AK11 -> 7.3263889 | AM11: 30936 | AN11: -0.03 | AO11: 1 | AP11: 0 | AQ11: 0 | AR11: 0 | AS11: 0 | AT11: =AT10 -> 16/17
B12: 9 | C12: AFC Bournemouth | D12: 55 | E12: 67 | F12: -12 | G12: 10 | H12: 52 | I12: 3 | J12: NA | K12: NA | L12: NA | M12: 452 | N12: 160 | O12: 7 | P12: 5 | Q12: 51 | S12: 4 | T12: 54 | U12: 4 | V12: 5 | W12: 122 | X12: 1091 | Y12: 605 | Z12: 372 | AA12: 17145 | AB12: 51 | AC12: 2651 | AD12: 642 | AE12: 193 | AF12: 40.69 | AG12: 23.69 | AH12: 19 | AI12: 30 | AJ12: 131.6 | AK12: 41 | AL12: =AJ12/AK12 -> 3.2097561 | AM12: 11182 | AN12: 0.2 | AO12: 0 | AP12: 0 | AQ12: 0 | AR12: 0 | AS12: 0 | AT12: =AT11 -> 16/17
B13: 10 | C13: West Bromwich Albion | D13: 43 | E13: 51 | F13: -8 | G13: 6 | H13: 80 | I13: 0 | J13: NA | K13: NA | L13: NA | M13: 399 | N13: 124 | O13: 1 | P13: 16 | Q13: 37 | S13: 6 | T13: 61 | U13: 1 | V13: 3 | W13: 109 | X13: 997 | Y13: 607 | Z13: 448 | AA13: 11821 | AB13: 37 | AC13: 1800 | AD13: 770 | AE13: 159 | AF13: 37.9 | AG13: 26.98 | AH13: 13 | AI13: 14 | AJ13: 123.2 | AK13: 30 | AL13: =AJ13/AK13 -> 4.1066667 | AM13: 23876 | AN13: 0.2 | AO13: 0 | AP13: 0 | AQ13: 0 | AR13: 0 | AS13: 0 | AT13: =AT12 -> 16/17
B14: 11 | C14: West Ham United | D14: 47 | E14: 64 | F14: -17 | G14: 10 | H14: 78 | I14: 5 | J14: NA | K14: NA | L14: NA | M14: 498 | N14: 136 | O14: 3 | P14: 13 | Q14: 40 | S14: 7 | T14: 80 | U14: 0 | V14: 8 | W14: 118 | X14: 1071 | Y14: 575 | Z14: 408 | AA14: 15134 | AB14: 38 | AC14: 2318 | AD14: 759 | AE14: 172 | AF14: 83.5 | AG14: 41 | AH14: 22 | AI14: 15 | AJ14: 273.05 | AK14: 44 | AL14: =AJ14/AK14 -> 6.2056818 | AM14: 56972 | AN14: -0.08 | AO14: 1 | AP14: 0 | AQ14: 0 | AR14: 0 | AS14: 0 | AT14: =AT13 -> 16/17
B15: 12 | C15: Leicester City | D15: 48 | E15: 63 | F15: -15 | G15: 9 | H15: 72 | I15: 1 | J15: NA | K15: NA | L15: NA | M15: 435 | N15: 145 | O15: 4 | P15: 10 | Q15: 39 | S15: 9 | T15: 65 | U15: 2 | V15: 3 | W15: 127 | X15: 1028 | Y15: 677 | Z15: 447 | AA15: 14558 | AB15: 25 | AC15: 1916 | AD15: 735 | AE15: 197 | AF15: 92.1 | AG15: 66.05 | AH15: 17 | AI15: 18 | AJ15: 218.65 | AK15: 31 | AL15: =AJ15/AK15 -> 7.0532258 | AM15: 31893 | AN15: 0.25 | AO15: 1 | AP15: 0 | AQ15: 0 | AR15: 0 | AS15: 0 | AT15: =AT14 -> 16/17
B16: 13 | C16: Stoke City | D16: 41 | E16: 56 | F16: -15 | G16: 11 | H16: 70 | I16: 2 | J16: NA | K16: NA | L16: NA | M16: 426 | N16: 135 | O16: 4 | P16: 7 | Q16: 36 | S16: 5 | T16: 87 | U16: 5 | V16: 2 | W16: 124 | X16: 1009 | Y16: 665 | Z16: 434 | AA16: 14558 | AB16: 53 | AC16: 2170 | AD16: 725 | AE16: 188 | AF16: 38.78 | AG16: 3.8 | AH16: 14 | AI16: 13 | AJ16: 186 | AK16: 34 | AL16: =AJ16/AK16 -> 5.4705882 | AM16: 27433 | AN16: 0.16 | AO16: 0 | AP16: 0 | AQ16: 0 | AR16: 0 | AS16: 0 | AT16: =AT15 -> 16/17
... B23: 20 | C23: Sunderland | D23: 29 | E23: 69 | F23: -40 | G23: 6 | H23: 78 | I23: 4 | J23: NA | K23: NA | L23: NA | M23: 388 | N23: 122 | O23: 5 | P23: 1 | Q23: 26 | S23: 3 | T23: 80 | U23: 2 | V23: 4 | W23: 179 | X23: 1173 | Y23: 630 | Z23: 437 | AA23: 12360 | AB23: 38 | AC23: 1882 | AD23: 633 | AE23: 159 | AF23: 41.9 | AG23: 23.77 | AH23: 25 | AI23: 23 | AJ23: 132 | AK23: 42 | AL23: =AJ23/AK23 -> 3.1428571 | AM23: 41287 | AN23: 0.07 | AO23: 0 | AP23: 0 | AQ23: 0 | AR23: 1 | AS23: 0 | AT23: =AT22 -> 16/17

Sheet 2017-2018
B2: Temporada 2017/2018 | D2: General | M2: Ataque | U2: Defensa | AA2: Tipo de juego | AF2: Extra cancha
B3: Posición en la tabla | C3: Equipo | D3: Goles a favor | E3: Goles en contra | F3: Diferencia de goles | G3: Porterias en cero | H3: Tarjetas Amarillas | I3: Tarjetas Rojas | J3: XG F | K3: XG A | L3: G vs XG | M3: Tiros | N3: Tiros a gol | O3: Gol de penal | P3: Gol de cabeza | Q3: Gol dentro del área | R3: Gol fuera del área | S3: Gol de contragolpe | T3: Fueras de lugar | U3: Auotgoles | V3: Penales provocados | W3: Paradas | X3: Despejes | Y3: Barridas | Z3: Faltas | AA3: # de pases | AB3: Pases filtrados | AC3: Pases hacia atrás | AD3: Centros | AE3: Corners | AF3: Dinero gastado en transferencias (Millones de euros) | AG3: Dinero ingresado por transferencias (millones de euros) | AH3: Jugadores nuevos | AI3: Jugadores vendidos | AJ3: Valor de la plantilla | AK3: # de jugadores | AL3: Valor promedio jugadores | AM3: Asistencia promedio al estadio | AN3: % ventaja local | AO3: Competencias Europeas | AP3: Recien ascendido | AQ3: Champions | AR3: Descenso | AS3: Big 6 | AT3: Temporada
B4: 1 | C4: Manchester City | D4: 106 | E4: 27 | F4: 79 | G4: 18 | H4: 59 | I4: 2 | J4: 78.6 | K4: 23.8 | L4: 27.4 | M4: 656 | N4: 656 | O4: 6 | P4: 12 | Q4: 93 | R4: 13 | S4: 4 | T4: 67 | U4: 2 | V4: 2 | W4: 58 | X4: 620 | Y4: 195 | Z4: 344 | AA4: 26164 | AB4: 118 | AC4: 4546 | AD4: 691 | AE4: 284 | AF4: 317.5 | AG4: 91.35 | AH4: 31 | AI4: 32 | AJ4: 1010 | AK4: 32 | AL4: =AJ4/AK4 -> 31.5625 | AM4: 54070 | AN4: 0.06 | AO4: 1 | AP4: 0 | AQ4: 1 | AR4: 0 | AS4: 1 | AT4: 17/18
B5: 2 | C5: Manchester United | D5: 68 | E5: 28 | F5: 40 | G5: 19 | H5: 64 | I5: 1 | J5: 55.7 | K5: 40.7 | L5: 12.3 | M5: 509 | N5: 509 | O5: 1 | P5: 12 | Q5: 56 | R5: 13 | S5: 4 | T5: 88 | U5: 2 | V5: 1 | W5: 117 | X5: 926 | Y5: 173 | Z5: 405 | AA5: 17765 | AB5: 85 | AC5: 2878 | AD5: 753 | AE5: 220 | AF5: 198.4 | AG5: 45.5 | AH5: 13 | AI5: 11 | AJ5: 849.5 | AK5: 35 | AL5: =AJ5/AK5 -> 24.271429 | AM5: 74976 | AN5: 0.24 | AO5: 1 | AP5: 0 | AQ5: 1 | AR5: 0 | AS5: 1 | AT5: =AT4 -> 17/18
B6: 3 | C6: Tottenham Hotspur | D6: 74 | E6: 36 | F6: 38 | G6: 16 | H6: 50 | I6: 2 | J6: 64.7 | K6: 33.9 | L6: 9.3 | M6: 620 | N6: 620 | O6: 2 | P6: 11 | Q6: 64 | R6: 11 | S6: 8 | T6: 88 | U6: 1 | V6: 3 | W6: 89 | X6: 878 | Y6: 212 | Z6: 384 | AA6: 19284 | AB6: 83 | AC6: 3176 | AD6: 825 | AE6: 246 | AF6: 123.5 | AG6: 103.8 | AH6: 14 | AI6: 11 | AJ6: 829.6 | AK6: 34 | AL6: =AJ6/AK6 -> 24.4 | AM6: 67953 | AN6: 0.12 | AO6: 1 | AP6: 0 | AQ6: 1 | AR6: 0 | AS6: 1 | AT6: =AT5 -> 17/18
B7: 4 | C7: Liverpool | D7: 84 | E7: 38 | F7: 46 | G7: 17 | H7: 44 | I7: 1 | J7: 72.9 | K7: 33.8 | L7: 11.1 | M7: 635 | N7: 635 | O7: 2 | P7: 12 | Q7: 75 | R7: 9 | S7: 9 | T7: 70 | U7: 0 | V7: 6 | W7: 64 | X7: 788 | Y7: 196 | Z7: 344 | AA7: 20367 | AB7: 106 | AC7: 3313 | AD7: 764 | AE7: 230 | AF7: 173.88 | AG7: 184.5 | AH7: 15 | AI7: 13 | AJ7: 857.5 | AK7: 35 | AL7: =AJ7/AK7 -> 24.5 | AM7: 53049 | AN7: 0.27 | AO7: 1 | AP7: 0 | AQ7: 1 | AR7: 0 | AS7: 1 | AT7: =AT6 -> 17/18
B8: 5 | C8: Chelsea | D8: 62 | E8: 38 | F8: 24 | G8: 16 | H8: 42 | I8: 4 | J8: 54.4 | K8: 33.8 | L8: 7.6 | M8: 603 | N8: 603 | O8: 3 | P8: 17 | Q8: 52 | R8: 10 | S8: 1 | T8: 108 | U8: 2 | V8: 2 | W8: 81 | X8: 842 | Y8: 208 | Z8: 363 | AA8: 18967 | AB8: 70 | AC8: 3019 | AD8: 755 | AE8: 230 | AF8: 260.5 | AG8: 194.6 | AH8: 40 | AI8: 31 | AJ8: 884.25 | AK8: 46 | AL8: =AJ8/AK8 -> 19.222826 | AM8: 41282 | AN8: 0.07 | AO8: 1 | AP8: 0 | AQ8: 0 | AR8: 0 | AS8: 1 | AT8: =AT7 -> 17/18
B9: 6 | C9: Arsenal | D9: 74 | E9: 51 | F9: 23 | G9: 13 | H9: 57 | I9: 2 | J9: 68.3 | K9: 47.8 | L9: 5.7 | M9: 589 | N9: 589 | O9: 4 | P9: 13 | Q9: 68 | R9: 7 | S9: 0 | T9: 89 | U9: 0 | V9: 6 | W9: 94 | X9: 879 | Y9: 218 | Z9: 383 | AA9: 20878 | AB9: 117 | AC9: 3089 | AD9: 572 | AE9: 225 | AF9: 152.85 | AG9: 162 | AH9: 10 | AI9: 16 | AJ9: 694 | AK9: 45 | AL9: =AJ9/AK9 -> 15.422222 | AM9: 59323 | AN9: 0.34 | AO9: 1 | AP9: 0 | AQ9: 0 | AR9: 0 | AS9: 1 | AT9: =AT8 -> 17/18
B10: 7 | C10: Burnley | D10: 36 | E10: 39 | F10: -3 | G10: 12 | H10: 65 | I10: 0 | J10: 32.3 | K10: 51.2 | L10: 3.7 | M10: 378 | N10: 378 | O10: 0 | P10: 10 | Q10: 32 | R10: 4 | S10: 0 | T10: 100 | U10: 1 | V10: 5 | W10: 121 | X10: 1300 | Y10: 204 | Z10: 350 | AA10: 10524 | AB10: 18 | AC10: 2245 | AD10: 707 | AE10: 167 | AF10: 35.74 | AG10: 50 | AH10: 18 | AI10: 21 | AJ10: 169.3 | AK10: 30 | AL10: =AJ10/AK10 -> 5.6433333 | AM10: 20688 | AN10: 0.01 | AO10: 0 | AP10: 0 | AQ10: 0 | AR10: 0 | AS10: 0 | AT10: =AT9 -> 17/18
B11: 8 | C11: Everton | D11: 44 | E11: 58 | F11: -14 | G11: 10 | H11: 51 | I11: 3 | J11: 40.5 | K11: 52.4 | L11: 3.5 | M11: 351 | N11: 351 | O11: 5 | P11: 8 | Q11: 36 | R11: 8 | S11: 2 | T11: 82 | U11: 0 | V11: 5 | W11: 119 | X11: 1308 | Y11: 223 | Z11: 460 | AA11: 11953 | AB11: 25 | AC11: 2212 | AD11: 629 | AE11: 150 | AF11: 203.2 | AG11: 126.38 | AH11: 23 | AI11: 20 | AJ11: 381.25 | AK11: 48 | AL11: =AJ11/AK11 -> 7.9427083 | AM11: 38797 | AN11: 0.26 | AO11: 1 | AP11: 0 | AQ11: 0 | AR11: 0 | AS11: 0 | AT11: =AT10 -> 17/18
B12: 9 | C12: Leicester City | D12: 56 | E12: 60 | F12: -4 | G12: 9 | H12: 52 | I12: 5 | J12: 50 | K12: 48.1 | L12: 6 | M12: 417 | N12: 417 | O12: 5 | P12: 9 | Q12: 49 | R12: 7 | S12: 7 | T12: 92 | U12: 2 | V12: 4 | W12: 104 | X12: 1007 | Y12: 208 | Z12: 364 | AA12: 12357 | AB12: 63 | AC12: 2094 | AD12: 744 | AE12: 203 | AF12: 83.85 | AG12: 50.1 | AH12: 14 | AI12: 13 | AJ12: 304.25 | AK12: 34 | AL12: =AJ12/AK12 -> 8.9485294 | AM12: 31583 | AN12: 0.09 | AO12: 0 | AP12: 0 | AQ12: 0 | AR12: 0 | AS12: 0 | AT12: =AT11 -> 17/18
B13: 10 | C13: Newcastle United | D13: 39 | E13: 47 | F13: -8 | G13: 9 | H13: 52 | I13: 2 | J13: 41.6 | K13: 52.4 | L13: -2.6 | M13: 450 | N13: 450 | O13: 0 | P13: 7 | Q13: 34 | R13: 5 | S13: 5 | T13: 63 | U13: 3 | V13: 6 | W13: 102 | X13: 1219 | Y13: 221 | Z13: 409 | AA13: 11071 | AB13: 67 | AC13: 2018 | AD13: 616 | AE13: 167 | AF13: 46.5 | AG13: 21.22 | AH13: 27 | AI13: 29 | AJ13: 208.28 | AK13: 37 | AL13: =AJ13/AK13 -> 5.6291892 | AM13: 51992 | AN13: 0.18 | AO13: 0 | AP13: 1 | AQ13: 0 | AR13: 0 | AS13: 0 | AT13: =AT12 -> 17/18
B14: 11 | C14: Crystal Palace | D14: 45 | E14: 55 | F14: -10 | G14: 9 | H14: 72 | I14: 0 | J14: 53.5 | K14: 48.2 | L14: -8.5 | M14: 466 | N14: 466 | O14: 8 | P14: 4 | Q14: 39 | R14: 6 | S14: 3 | T14: 56 | U14: 2 | V14: 2 | W14: 117 | X14: 1110 | Y14: 260 | Z14: 425 | AA14: 11809 | AB14: 30 | AC14: 2091 | AD14: 703 | AE14: 210 | AF14: 48.95 | AG14: 3 | AH14: 15 | AI14: 18 | AJ14: 220.73 | AK14: 41 | AL14: =AJ14/AK14 -> 5.3836585 | AM14: 25063 | AN14: 0.16 | AO14: 0 | AP14: 0 | AQ14: 0 | AR14: 0 | AS14: 0 | AT14: =AT13 -> 17/18
B15: 12 | C15: Bournemouth | D15: 45 | E15: 61 | F15: -16 | G15: 6 | H15: 55 | I15: 1 | J15: 38.8 | K15: 59.2 | L15: 6.2 | M15: 462 | N15: 462 | O15: 3 | P15: 4 | Q15: 38 | R15: 7 | S15: 0 | T15: 52 | U15: 1 | V15: 3 | W15: 109 | X15: 1129 | Y15: 198 | Z15: 339 | AA15: 13450 | AB15: 37 | AC15: 2257 | AD15: 707 | AE15: 218 | AF15: 34.3 | AG15: 0 | AH15: 15 | AI15: 14 | AJ15: 144.5 | AK15: 25 | AL15: =AJ15/AK15 -> 5.78 | AM15: 10641 | AN15: 0.09 | AO15: 0 | AP15: 0 | AQ15: 0 | AR15: 0 | AS15: 0 | AT15: =AT14 -> 17/18
B16: 13 | C16: West Ham United | D16: 48 | E16: 68 | F16: -20 | G16: 10 | H16: 73 | I16: 2 | J16: 36.7 | K16: 55.1 | L16: 11.3 | M16: 368 | N16: 368 | O16: 2 | P16: 6 | Q16: 39 | R16: 10 | S16: 4 | T16: 97 | U16: 1 | V16: 6 | W16: 119 | X16: 1085 | Y16: 235 | Z16: 379 | AA16: 11779 | AB16: 51 | AC16: 2177 | AD16: 733 | AE16: 161 | AF16: 56.8 | AG16: 69.02 | AH16: 15 | AI16: 25 | AJ16: 260.6 | AK16: 41 | AL16: =AJ16/AK16 -> 6.3560976 | AM16: 56885 | AN16: 0.12 | AO16: 0 | AP16: 0 | AQ16: 0 | AR16: 0 | AS16: 0 | AT16: =AT15 -> 17/18
... B23: 20 | C23: West Bromwich Albion | D23: 31 | E23: 56 | F23: -25 | G23: 10 | H23: 73 | I23: 1 | J23: 36.5 | K23: 47.9 | L23: -5.5 | M23: 377 | N23: 377 | O23: 1 | P23: 10 | Q23: 29 | R23: 2 | S23: 2 | T23: 79 | U23: 2 | V23: 1 | W23: 100 | X23: 1087 | Y23: 218 | Z23: 440 | AA23: 10495 | AB23: 34 | AC23: 2041 | AD23: 784 | AE23: 176 | AF23: 53.5 | AG23: 2.05 | AH23: 17 | AI23: 11 | AJ23: 165.95 | AK23: 33 | AL23: =AJ23/AK23 -> 5.0287879 | AM23: 24520 | AN23: 0.16 | AO23: 0 | AP23: 0 | AQ23: 0 | AR23: 1 | AS23: 0 | AT23: =AT22 -> 17/18

Sheet 2018-2019
B2: Temporada 2018/2019 | D2: General | M2: Ataque | U2: Defensa | AA2: Tipo de juego | AF2: Extra cancha
B3: Posición en la tabla | C3: Equipo | D3: Goles a favor | E3: Goles en contra | F3: Diferencia de goles | G3: Porterias en cero | H3: Tarjetas Amarillas | I3: Tarjetas Rojas | J3: XG F | K3: XG A | L3: G vs XG | M3: Tiros | N3: Tiros a gol | O3: Gol de penal | P3: Gol de cabeza | Q3: Gol dentro del área | R3: Gol fuera del área | S3: Gol de contragolpe | T3: Fueras de lugar | U3: Auotgoles | V3: Penales provocados | W3: Paradas | X3: Despejes | Y3: Barridas | Z3: Faltas | AA3: # de pases | AB3: Pases filtrados | AC3: Pases hacia atrás | AD3: Centros | AE3: Corners | AF3: Dinero gastado en transferencias (Millones de euros) | AG3: Dinero ingresado por transferencias (millones de euros) | AH3: Jugadores nuevos | AI3: Jugadores vendidos | AJ3: Valor de la plantilla | AK3: # de jugadores | AL3: Valor promedio jugadores | AM3: Asistencia promedio al estadio | AN3: % ventaja local | AO3: Competencias Europeas | AP3: Recien ascendido | AQ3: Champions | AR3: Descenso | AS3: Big 6 | AT3: Temporada
A4: Manchester City | B4: 1 | C4: Manchester City | D4: 95 | E4: 23 | F4: 72 | G4: 20 | H4: 44 | I4: 1 | J4: 84.3 | K4: 24.7 | L4: 10.7 | M4: 679 | N4: 252 | O4: 3 | P4: 12 | Q4: 80 | R4: 15 | S4: 5 | T4: 98 | U4: 0 | V4: 4 | W4: 58 | X4: 570 | Y4: 518 | Z4: 328 | AA4: 24678 | AB4: 112 | AC4: 4240 | AD4: 783 | AE4: 298 | AF4: 78.59 | AG4: 57.6 | AH4: 19 | AI4: 22 | AJ4: 1200 | AK4: 46 | AL4: 26.086957 | AM4: 54130 | AN4: 0.09 | AO4: 1 | AP4: 0 | AQ4: 1 | AR4: 0 | AS4: 1 | AT4: 18/19
A5: Liverpool | B5: 2 | C5: Liverpool | D5: 89 | E5: 22 | F5: 67 | G5: 21 | H5: 38 | I5: 2 | J5: 73.7 | K5: 28.8 | L5: 15.3 | M5: 568 | N5: 211 | O5: 7 | P5: 19 | Q5: 84 | R5: 5 | S5: 6 | T5: 77 | U5: 0 | V5: 1 | W5: 74 | X5: 670 | Y5: 613 | Z5: 315 | AA5: 21146 | AB5: 98 | AC5: 3416 | AD5: 721 | AE5: 249 | AF5: 182.2 | AG5: 41.32 | AH5: 18 | AI5: 21 | AJ5: 1170 | AK5: 39 | AL5: 30 | AM5: 52983 | AN5: 0.17 | AO5: 1 | AP5: 0 | AQ5: 1 | AR5: 0 | AS5: 1 | AT5: =AT4 -> 18/19
A6: Chelsea | B6: 3 | C6: Chelsea | D6: 63 | E6: 39 | F6: 24 | G6: 16 | H6: 49 | I6: 0 | J6: 58.6 | K6: 36.4 | L6: 4.4 | M6: 602 | N6: 192 | O6: 5 | P6: 8 | Q6: 54 | R6: 9 | S6: 1 | T6: 83 | U6: 0 | V6: 2 | W6: 84 | X6: 645 | Y6: 618 | Z6: 339 | AA6: 22960 | AB6: 146 | AC6: 3874 | AD6: 692 | AE6: 215 | AF6: 208.8 | AG6: 83.25 | AH6: 30 | AI6: 31 | AJ6: 1170 | AK6: 54 | AL6: 21.666667 | AM6: 40437 | AN6: 0.31 | AO6: 1 | AP6: 0 | AQ6: 1 | AR6: 0 | AS6: 1 | AT6: =AT5 -> 18/19
A7: Tottenham Hotspur | B7: 4 | C7: Tottenham Hotspur | D7: 67 | E7: 39 | F7: 28 | G7: 13 | H7: 56 | I7: 3 | J7: 54.9 | K7: 47.1 | L7: 12.1 | M7: 533 | N7: 182 | O7: 4 | P7: 14 | Q7: 53 | R7: 14 | S7: 5 | T7: 74 | U7: 3 | V7: 5 | W7: 118 | X7: 823 | Y7: 627 | Z7: 376 | AA7: 18808 | AB7: 87 | AC7: 3191 | AD7: 643 | AE7: 194 | AF7: 0 | AG7: 5.35 | AH7: 4 | AI7: 4 | AJ7: 898.6 | AK7: 34 | AL7: 26.429412 | AM7: 54216 | AN7: 0.1 | AO7: 1 | AP7: 0 | AQ7: 1 | AR7: 0 | AS7: 1 | AT7: =AT6 -> 18/19
A8: Arsenal | B8: 5 | C8: Arsenal | D8: 73 | E8: 51 | F8: 22 | G8: 8 | H8: 72 | I8: 2 | J8: 60.1 | K8: 54.2 | L8: 12.9 | M8: 462 | N8: 159 | O8: 4 | P8: 5 | Q8: 62 | R8: 11 | S8: 3 | T8: 89 | U8: 1 | V8: 7 | W8: 132 | X8: 798 | Y8: 609 | Z8: 412 | AA8: 18425 | AB8: 65 | AC8: 3102 | AD8: 605 | AE8: 209 | AF8: 80.15 | AG8: 9.1 | AH8: 17 | AI8: 12 | AJ8: 659.05 | AK8: 42 | AL8: 15.691667 | AM8: 59899 | AN8: 0.26 | AO8: 1 | AP8: 0 | AQ8: 0 | AR8: 0 | AS8: 1 | AT8: =AT7 -> 18/19
A9: Manchester United | B9: 6 | C9: Manchester United | D9: 65 | E9: 54 | F9: 11 | G9: 7 | H9: 73 | I9: 4 | J9: 61.4 | K9: 50.6 | L9: 3.6 | M9: 514 | N9: 210 | O9: 9 | P9: 4 | Q9: 55 | R9: 10 | S9: 4 | T9: 90 | U9: 3 | V9: 6 | W9: 120 | X9: 847 | Y9: 581 | Z9: 433 | AA9: 16834 | AB9: 63 | AC9: 2634 | AD9: 638 | AE9: 200 | AF9: 82.7 | AG9: 30.55 | AH9: 9 | AI9: 10 | AJ9: 797.6 | AK9: 36 | AL9: 22.155556 | AM9: 74498 | AN9: 0.05 | AO9: 1 | AP9: 0 | AQ9: 0 | AR9: 0 | AS9: 1 | AT9: =AT8 -> 18/19
A10: Wolverhampton Wanderers | B10: 7 | C10: Wolverhampton Wanderers | D10: 47 | E10: 46 | F10: 1 | G10: 9 | H10: 72 | I10: 1 | J10: 52.1 | K10: 42.1 | L10: -5.1 | M10: 473 | N10: 144 | O10: 4 | P10: 10 | Q10: 44 | R10: 3 | S10: 5 | T10: 73 | U10: 4 | V10: 4 | W10: 99 | X10: 895 | Y10: 720 | Z10: 409 | AA10: 13961 | AB10: 51 | AC10: 2515 | AD10: 622 | AE10: 195 | AF10: 112.75 | AG10: 23.3 | AH10: 35 | AI10: 46 | AJ10: 302.9 | AK10: 40 | AL10: 7.5725 | AM10: 31030 | AN10: 0.14 | AO10: 0 | AP10: 1 | AQ10: 0 | AR10: 0 | AS10: 0 | AT10: =AT9 -> 18/19
A11: Everton | B11: 8 | C11: Everton | D11: 54 | E11: 46 | F11: 8 | G11: 14 | H11: 55 | I11: 4 | J11: 49.7 | K11: 45.7 | L11: 4.3 | M11: 493 | N11: 163 | O11: 2 | P11: 13 | Q11: 45 | R11: 10 | S11: 3 | T11: 69 | U11: 2 | V11: 5 | W11: 89 | X11: 877 | Y11: 699 | Z11: 432 | AA11: 13878 | AB11: 44 | AC11: 2362 | AD11: 814 | AE11: 215 | AF11: 99.8 | AG11: 28.65 | AH11: 19 | AI11: 23 | AJ11: 529.1 | AK11: 40 | AL11: 13.2275 | AM11: 39043 | AN11: 0.1 | AO11: 0 | AP11: 0 | AQ11: 0 | AR11: 0 | AS11: 0 | AT11: =AT10 -> 18/19
A12: Leicester City | B12: 9 | C12: Leicester City | D12: 51 | E12: 48 | F12: 3 | G12: 10 | H12: 57 | I12: 5 | J12: 52.4 | K12: 43.7 | L12: -1.4 | M12: 508 | N12: 173 | O12: 5 | P12: 9 | Q12: 43 | R12: 8 | S12: 8 | T12: 72 | U12: 0 | V12: 5 | W12: 90 | X12: 1034 | Y12: 675 | Z12: 351 | AA12: 14640 | AB12: 88 | AC12: 2593 | AD12: 779 | AE12: 210 | AF12: 114.6 | AG12: 95.8 | AH12: 16 | AI12: 18 | AJ12: 434.1 | AK12: 37 | AL12: 11.732432 | AM12: 31851 | AN12: 0.06 | AO12: 0 | AP12: 0 | AQ12: 0 | AR12: 0 | AS12: 0 | AT12: =AT11 -> 18/19
A13: West Ham United | B13: 10 | C13: West Ham United | D13: 52 | E13: 55 | F13: -3 | G13: 7 | H13: 59 | I13: 1 | J13: 47.6 | K13: 61.9 | L13: 4.4 | M13: 436 | N13: 149 | O13: 5 | P13: 10 | Q13: 47 | R13: 5 | S13: 3 | T13: 71 | U13: 1 | V13: 5 | W13: 143 | X13: 926 | Y13: 723 | Z13: 331 | AA13: 13847 | AB13: 75 | AC13: 2273 | AD13: 631 | AE13: 188 | AF13: 100.9 | AG13: 13.77 | AH13: 18 | AI13: 13 | AJ13: 359 | AK13: 37 | AL13: 9.7027027 | AM13: 58336 | AN13: 0.13 | AO13: 0 | AP13: 0 | AQ13: 0 | AR13: 0 | AS13: 0 | AT13: =AT12 -> 18/19
A14: Watford | B14: 11 | C14: Watford | D14: 52 | E14: 59 | F14: -7 | G14: 7 | H14: 77 | I14: 4 | J14: 48.2 | K14: 59.2 | L14: 3.8 | M14: 436 | N14: 148 | O14: 1 | P14: 8 | Q14: 44 | R14: 8 | S14: 3 | T14: 89 | U14: 3 | V14: 5 | W14: 123 | X14: 1022 | Y14: 656 | Z14: 433 | AA14: 12550 | AB14: 32 | AC14: 2314 | AD14: 570 | AE14: 177 | AF14: 30.1 | AG14: 51.84 | AH14: 26 | AI14: 27 | AJ14: 239.1 | AK14: 39 | AL14: 6.1307692 | AM14: 20016 | AN14: 0.03 | AO14: 0 | AP14: 0 | AQ14: 0 | AR14: 0 | AS14: 0 | AT14: =AT13 -> 18/19
A15: Crystal Palace | B15: 12 | C15: Crystal Palace | D15: 51 | E15: 53 | F15: -2 | G15: 12 | H15: 58 | I15: 2 | J15: 47.6 | K15: 50.1 | L15: 3.4 | M15: 482 | N15: 135 | O15: 10 | P15: 5 | Q15: 43 | R15: 8 | S15: 2 | T15: 78 | U15: 1 | V15: 5 | W15: 110 | X15: 1011 | Y15: 733 | Z15: 386 | AA15: 12697 | AB15: 26 | AC15: 2233 | AD15: 577 | AE15: 205 | AF15: 11.85 | AG15: 0.35 | AH15: 11 | AI15: 16 | AJ15: 289 | AK15: 36 | AL15: 8.0277778 | AM15: 25455 | AN15: -0.06 | AO15: 0 | AP15: 0 | AQ15: 0 | AR15: 0 | AS15: 0 | AT15: =AT14 -> 18/19
A16: Newcastle United | B16: 13 | C16: Newcastle United | D16: 42 | E16: 48 | F16: -6 | G16: 11 | H16: 57 | I16: 2 | J16: 39.1 | K16: 53.6 | L16: 2.9 | M16: 443 | N16: 136 | O16: 1 | P16: 12 | Q16: 40 | R16: 2 | S16: 1 | T16: 59 | U16: 1 | V16: 6 | W16: 93 | X16: 1204 | Y16: 711 | Z16: 423 | AA16: 10774 | AB16: 50 | AC16: 1999 | AD16: 711 | AE16: 181 | AF16: 59.45 | AG16: 54.05 | AH16: 22 | AI16: 23 | AJ16: 244.65 | AK16: 37 | AL16: 6.6121622 | AM16: 51121 | AN16: 0.05 | AO16: 0 | AP16: 0 | AQ16: 0 | AR16: 0 | AS16: 0 | AT16: =AT15 -> 18/19
... A23: Huddersfield Town | B23: 20 | C23: Huddersfield Town | D23: 22 | E23: 76 | F23: -54 | G23: 5 | H23: 55 | I23: 4 | J23: 28.8 | K23: 60.9 | L23: -6.8 | M23: 400 | N23: 116 | O23: 1 | P23: 8 | Q23: 17 | R23: 5 | S23: 1 | T23: 63 | U23: 1 | V23: 8 | W23: 110 | X23: 682 | Y23: 708 | Z23: 420 | AA23: 13045 | AB23: 23 | AC23: 2492 | AD23: 768 | AE23: 162 | AF23: 50.7 | AG23: 12.33 | AH23: 14 | AI23: 16 | AJ23: 137.45 | AK23: 33 | AL23: 4.1651515 | AM23: 23203 | AN23: 0.05 | AO23: 0 | AP23: 0 | AQ23: 0 | AR23: 1 | AS23: 0 | AT23: =AT22 -> 18/19

Sheet 2019-2020
B2: Temporada 2019/2020 | D2: General | M2: Ataque | U2: Defensa | AA2: Tipo de juego | AF2: Extra cancha
B3: Posición en la tabla | C3: Equipo | D3: Goles a favor | E3: Goles en contra | F3: Diferencia de goles | G3: Porterias en cero | H3: Tarjetas Amarillas | I3: Tarjetas Rojas | J3: XG F | K3: XG A | L3: G vs XG | M3: Tiros | N3: Tiros a gol | O3: Gol de penal | P3: Gol de cabeza | Q3: Gol dentro del área | R3: Gol fuera del área | S3: Gol de contragolpe | T3: Fueras de lugar | U3: Auotgoles | V3: Penales provocados | W3: Paradas | X3: Despejes | Y3: Barridas | Z3: Faltas | AA3: # de pases | AB3: Pases filtrados | AC3: Pases hacia atrás | AD3: Centros | AE3: Corners | AF3: Dinero gastado en transferencias (Millones de euros) | AG3: Dinero ingresado por transferencias (millones de euros) | AH3: Jugadores nuevos | AI3: Jugadores vendidos | AJ3: Valor de la plantilla | AK3: # de jugadores | AL3: Valor promedio jugadores | AM3: Asistencia promedio al estadio | AN3: % ventaja local | AO3: Competencias Europeas | AP3: Recien ascendido | AQ3: Champions | AR3: Descenso | AS3: Big 6 | AT3: Temporada
A4: Liverpool | B4: 1 | C4: Liverpool | D4: 85 | E4: 33 | F4: =D4-E4 -> 52 | G4: 15 | H4: 38 | I4: 1 | J4: 68.9 | K4: 37.7 | L4: 16.1 | M4: 586 | N4: 224 | O4: 5 | P4: 19 | Q4: 72 | R4: 14 | S4: 11 | T4: 53 | U4: 1 | V4: 1 | W4: 75 | X4: 634 | Y4: 550 | Z4: 331 | AA4: 21276 | AB4: 68 | AC4: 3395 | AD4: 896 | AE4: 257 | AF4: 10.4 | AG4: 44.5 | AH4: 15 | AI4: 16 | AJ4: 1000 | AK4: 56 | AL4: =AJ4/AK4 -> 17.857143 | AM4: 41955 | AN4: 0.13 | AO4: 1 | AP4: 0 | AQ4: 1 | AR4: 0 | AS4: 1 | AT4: 19/20
A5: Manchester City | B5: 2 | C5: Manchester City | D5: 102 | E5: 35 | F5: =D5-E5 -> 67 | G5: 17 | H5: 60 | I5: 4 | J5: 92 | K5: 36.2 | L5: 10 | M5: 735 | N5: 250 | O5: 6 | P5: 11 | Q5: 85 | R5: 18 | S5: 4 | T5: 68 | U5: 1 | V5: 3 | W5: 76 | X5: 495 | Y5: 514 | Z5: 362 | AA5: 24557 | AB5: 85 | AC5: 4216 | AD5: 915 | AE5: 298 | AF5: 159.52 | AG5: 71 | AH5: 25 | AI5: 26 | AJ5: 1050 | AK5: 34 | AL5: =AJ5/AK5 -> 30.882353 | AM5: 37097 | AN5: 0.19 | AO5: 1 | AP5: 0 | AQ5: 1 | AR5: 0 | AS5: 1 | AT5: =AT4 -> 19/20
A6: Manchester United | B6: 3 | C6: Manchester United | D6: 66 | E6: 36 | F6: =D6-E6 -> 30 | G6: 13 | H6: 73 | I6: 0 | J6: 62.2 | K6: 37.7 | L6: 3.8 | M6: 530 | N6: 201 | O6: 10 | P6: 5 | Q6: 54 | R6: 12 | S6: 6 | T6: 56 | U6: 1 | V6: 3 | W6: 96 | X6: 703 | Y6: 579 | Z6: 423 | AA6: 17744 | AB6: 64 | AC6: 2790 | AD6: 635 | AE6: 204 | AF6: 234.8 | AG6: 81.18 | AH6: 13 | AI6: 12 | AJ6: 670.45 | AK6: 43 | AL6: =AJ6/AK6 -> 15.59186 | AM6: 57415 | AN6: 0.14 | AO6: 1 | AP6: 0 | AQ6: 1 | AR6: 0 | AS6: 1 | AT6: =AT5 -> 19/20
A7: Chelsea | B7: 4 | C7: Chelsea | D7: 69 | E7: 54 | F7: =D7-E7 -> 15 | G7: 9 | H7: 60 | I7: 0 | J7: 69.2 | K7: 38.6 | L7: -0.2 | M7: 618 | N7: 210 | O7: 7 | P7: 9 | Q7: 59 | R7: 10 | S7: 8 | T7: 63 | U7: 3 | V7: 2 | W7: 64 | X7: 631 | Y7: 638 | Z7: 386 | AA7: 20958 | AB7: 61 | AC7: 3668 | AD7: 862 | AE7: 247 | AF7: 45 | AG7: 157.27 | AH7: 22 | AI7: 29 | AJ7: 705.85 | AK7: 36 | AL7: =AJ7/AK7 -> 19.606944 | AM7: 32023 | AN7: 0.14 | AO7: 1 | AP7: 0 | AQ7: 1 | AR7: 0 | AS7: 1 | AT7: =AT6 -> 19/20
A8: Leicester City | B8: 5 | C8: Leicester City | D8: 67 | E8: 41 | F8: =D8-E8 -> 26 | G8: 13 | H8: 41 | I8: 3 | J8: 62.2 | K8: 45.5 | L8: 4.8 | M8: 533 | N8: 183 | O8: 5 | P8: 11 | Q8: 59 | R8: 9 | S8: 9 | T8: 64 | U8: 2 | V8: 10 | W8: 94 | X8: 767 | Y8: 742 | Z8: 418 | AA8: 17600 | AB8: 68 | AC8: 2975 | AD8: 779 | AE8: 221 | AF8: 104.3 | AG8: 88.5 | AH8: 13 | AI8: 13 | AJ8: 411.1 | AK8: 32 | AL8: =AJ8/AK8 -> 12.846875 | AM8: 25312 | AN8: 0.12 | AO8: 0 | AP8: 0 | AQ8: 0 | AR8: 0 | AS8: 0 | AT8: =AT7 -> 19/20
A9: Tottenham Hotspur | B9: 6 | C9: Tottenham Hotspur | D9: 61 | E9: 47 | F9: =D9-E9 -> 14 | G9: 8 | H9: 82 | I9: 3 | J9: 47.9 | K9: 54.2 | L9: 13.1 | M9: 440 | N9: 154 | O9: 3 | P9: 8 | Q9: 55 | R9: 6 | S9: 8 | T9: 66 | U9: 2 | V9: 7 | W9: 134 | X9: 894 | Y9: 665 | Z9: 423 | AA9: 16101 | AB9: 79 | AC9: 2584 | AD9: 641 | AE9: 200 | AF9: 148.5 | AG9: 64.5 | AH9: 12 | AI9: 14 | AJ9: 806.6 | AK9: 36 | AL9: =AJ9/AK9 -> 22.405556 | AM9: 43757 | AN9: 0.23 | AO9: 1 | AP9: 0 | AQ9: 0 | AR9: 0 | AS9: 1 | AT9: =AT8 -> 19/20
A10: Wolverhampton Wanderers | B10: 7 | C10: Wolverhampton Wanderers | D10: 52 | E10: 40 | F10: =D10-E10 -> 12 | G10: 13 | H10: 57 | I10: 2 | J10: 54.1 | K10: 38 | L10: -2.1 | M10: 457 | N10: 142 | O10: 4 | P10: 10 | Q10: 46 | R10: 7 | S10: 6 | T10: 49 | U10: 1 | V10: 3 | W10: 88 | X10: 702 | Y10: 646 | Z10: 407 | AA10: 14298 | AB10: 40 | AC10: 2601 | AD10: 718 | AE10: 193 | AF10: 116.7 | AG10: 24.1 | AH10: 28 | AI10: 26 | AJ10: 320.33 | AK10: 44 | AL10: =AJ10/AK10 -> 7.2802273 | AM10: 24758 | AN10: 0.06 | AO10: 1 | AP10: 0 | AQ10: 0 | AR10: 0 | AS10: 0 | AT10: =AT9 -> 19/20
A11: Arsenal | B11: 8 | C11: Arsenal | D11: 56 | E11: 48 | F11: =D11-E11 -> 8 | G11: 10 | H11: 86 | I11: 5 | J11: 47 | K11: 55.3 | L11: 9 | M11: 403 | N11: 146 | O11: 3 | P11: 5 | Q11: 51 | R11: 5 | S11: 2 | T11: 73 | U11: 0 | V11: 8 | W11: 144 | X11: 754 | Y11: 584 | Z11: 421 | AA11: 16634 | AB11: 67 | AC11: 3032 | AD11: 699 | AE11: 231 | AF11: 160.8 | AG11: 53.65 | AH11: 16 | AI11: 19 | AJ11: 607.65 | AK11: 38 | AL11: =AJ11/AK11 -> 15.990789 | AM11: 47589 | AN11: 0 | AO11: 1 | AP11: 0 | AQ11: 0 | AR11: 0 | AS11: 1 | AT11: =AT10 -> 19/20
A12: Sheffield Utd | B12: 9 | C12: Sheffield United | D12: 39 | E12: 39 | F12: =D12-E12 -> 0 | G12: 13 | H12: 61 | I12: 3 | J12: 43 | K12: 51 | L12: -4 | M12: 352 | N12: 109 | O12: 1 | P12: 5 | Q12: 38 | R12: 1 | S12: 3 | T12: 78 | U12: 0 | V12: 3 | W12: 99 | X12: 931 | Y12: 611 | Z12: 412 | AA12: 12125 | AB12: 15 | AC12: 2312 | AD12: 866 | AE12: 212 | AF12: 70.5 | AG12: 0.35 | AH12: 23 | AI12: 21 | AJ12: 138.6 | AK12: 34 | AL12: =AJ12/AK12 -> 4.0764706 | AM12: 24370 | AN12: 0.23 | AO12: 0 | AP12: 1 | AQ12: 0 | AR12: 0 | AS12: 0 | AT12: =AT11 -> 19/20
A13: Burnley | B13: 10 | C13: Burnley | D13: 43 | E13: 50 | F13: =D13-E13 -> -7 | G13: 15 | H13: 67 | I13: 0 | J13: 47.4 | K13: 49.8 | L13: -4.4 | M13: 384 | N13: 124 | O13: 3 | P13: 12 | Q13: 37 | R13: 6 | S13: 2 | T13: 89 | U13: 1 | V13: 5 | W13: 117 | X13: 901 | Y13: 547 | Z13: 412 | AA13: 10049 | AB13: 29 | AC13: 1983 | AD13: 743 | AE13: 170 | AF13: 23.85 | AG13: 13.55 | AH13: 8 | AI13: 10 | AJ13: 163.88 | AK13: 35 | AL13: =AJ13/AK13 -> 4.6822857 | AM13: 15995 | AN13: 0.1 | AO13: 0 | AP13: 0 | AQ13: 0 | AR13: 0 | AS13: 0 | AT13: =AT12 -> 19/20
A14: Southampton | B14: 11 | C14: Southampton | D14: 51 | E14: 60 | F14: =D14-E14 -> -9 | G14: 9 | H14: 53 | I14: 4 | J14: 56.1 | K14: 52.8 | L14: -5.1 | M14: 494 | N14: 171 | O14: 2 | P14: 4 | Q14: 39 | R14: 12 | S14: 2 | T14: 58 | U14: 1 | V14: 4 | W14: 108 | X14: 867 | Y14: 706 | Z14: 450 | AA14: 12488 | AB14: 27 | AC14: 2400 | AD14: 690 | AE14: 210 | AF14: 61.5 | AG14: 27.3 | AH14: 14 | AI14: 17 | AJ14: 210.75 | AK14: 36 | AL14: =AJ14/AK14 -> 5.8541667 | AM14: 23428 | AN14: -0.17 | AO14: 0 | AP14: 0 | AQ14: 0 | AR14: 0 | AS14: 0 | AT14: =AT13 -> 19/20
A15: Everton | B15: 12 | C15: Everton | D15: 44 | E15: 56 | F15: =D15-E15 -> -12 | G15: 9 | H15: 70 | I15: 3 | J15: 50.8 | K15: 48.3 | L15: -6.8 | M15: 468 | N15: 159 | O15: 1 | P15: 16 | Q15: 43 | R15: 1 | S15: 3 | T15: 58 | U15: 3 | V15: 4 | W15: 94 | X15: 778 | Y15: 671 | Z15: 472 | AA15: 13433 | AB15: 55 | AC15: 2275 | AD15: 804 | AE15: 203 | AF15: 121 | AG15: 87.8 | AH15: 22 | AI15: 22 | AJ15: 420.55 | AK15: 35 | AL15: =AJ15/AK15 -> 12.015714 | AM15: 28848 | AN15: 0.17 | AO15: 0 | AP15: 0 | AQ15: 0 | AR15: 0 | AS15: 0 | AT15: =AT14 -> 19/20
A16: Newcastle United | B16: 13 | C16: Newcastle United | D16: 38 | E16: 58 | F16: =D16-E16 -> -20 | G16: 11 | H16: 66 | I16: 3 | J16: 35.5 | K16: 65.6 | L16: 2.5 | M16: 398 | N16: 132 | O16: 0 | P16: 7 | Q16: 34 | R16: 4 | S16: 2 | T16: 75 | U16: 2 | V16: 2 | W16: 139 | X16: 988 | Y16: 603 | Z16: 370 | AA16: 10606 | AB16: 18 | AC16: 2015 | AD16: 591 | AE16: 151 | AF16: 72.9 | AG16: 35.64 | AH16: 13 | AI16: 11 | AJ16: 252.48 | AK16: 41 | AL16: =AJ16/AK16 -> 6.1580488 | AM16: 35551 | AN16: 0.16 | AO16: 0 | AP16: 0 | AQ16: 0 | AR16: 0 | AS16: 0 | AT16: =AT15 -> 19/20
... A23: Norwich City | B23: 20 | C23: Norwich City | D23: 26 | E23: 75 | F23: =D23-E23 -> -49 | G23: 5 | H23: 68 | I23: 3 | J23: 37 | K23: 66.5 | L23: -11 | M23: 407 | N23: 126 | O23: 2 | P23: 1 | Q23: 24 | R23: 2 | S23: 0 | T23: 50 | U23: 3 | V23: 7 | W23: 135 | X23: 959 | Y23: 628 | Z23: 363 | AA23: 14965 | AB23: 47 | AC23: 3005 | AD23: 473 | AE23: 162 | AF23: 8.82 | AG23: 2.2 | AH23: 23 | AI23: 28 | AJ23: 145.33 | AK23: 38 | AL23: =AJ23/AK23 -> 3.8244737 | AM23: 19913 | AN23: 0.43 | AO23: 0 | AP23: 1 | AQ23: 0 | AR23: 1 | AS23: 0 | AT23: =AT22 -> 19/20

Sheet 2020-2021
B2: Temporada 2020/2021 | D2: General | M2: Ataque | U2: Defensa | AA2: Tipo de juego | AF2: Extra cancha
B3: Posición en la tabla | C3: Equipo | D3: Goles a favor | E3: Goles en contra | F3: Diferencia de goles | G3: Porterias en cero | H3: Tarjetas Amarillas | I3: Tarjetas Rojas | J3: XG F | K3: XG A | L3: G vs XG | M3: Tiros | N3: Tiros a gol | O3: Gol de penal | P3: Gol de cabeza | Q3: Gol dentro del área | R3: Gol fuera del área | S3: Gol de contragolpe | T3: Fueras de lugar | U3: Auotgoles | V3: Penales provocados | W3: Paradas | X3: Despejes | Y3: Barridas | Z3: Faltas | AA3: # de pases | AB3: Pases filtrados | AC3: Pases hacia atrás | AD3: Centros | AE3: Corners | AF3: Dinero gastado en transferencias (Millones de euros) | AG3: Dinero ingresado por transferencias (millones de euros) | AH3: Jugadores nuevos | AI3: Jugadores vendidos | AJ3: Valor de la plantilla | AK3: # de jugadores | AL3: Valor promedio jugadores | AM3: Asistencia promedio al estadio | AN3: % ventaja local | AO3: Competencias Europeas | AP3: Recien ascendido | AQ3: Champions | AR3: Descenso | AS3: Big 6 | AT3: Temporada
A4: Manchester City | B4: 1 | C4: Manchester City | D4: 83 | E4: 32 | F4: =D4-E4 -> 51 | G4: 19 | H4: 46 | I4: 2 | J4: 68.2 | K4: 30.2 | L4: =D4-J4 -> 14.8 | M4: 590 | N4: 211 | O4: 5 | P4: 10 | Q4: 73 | R4: 10 | S4: 3 | T4: 57 | U4: 1 | V4: 10 | W4: 67 | X4: 453 | Y4: 498 | Z4: 361 | AA4: 23819 | AB4: 38 | AC4: 4275 | AD4: 632 | AE4: 247 | AF4: 172.3 | AG4: 76.65 | AH4: 28 | AI4: 27 | AJ4: 1040 | AK4: 36 | AL4: =AJ4/AK4 -> 28.888889 | AM4: 526 | AN4: -0.01 | AO4: 1 | AP4: 0 | AQ4: 1 | AR4: 0 | AS4: 1 | AT4: 20/21
A5: Manchester United | B5: 2 | C5: Manchester United | D5: 73 | E5: 44 | F5: =D5-E5 -> 29 | G5: 13 | H5: 64 | I5: 1 | J5: 60.1 | K5: 41.4 | L5: =D5-J5 -> 12.9 | M5: 515 | N5: 196 | O5: 10 | P5: 13 | Q5: 65 | R5: 8 | S5: 6 | T5: 76 | U5: 2 | V5: 4 | W5: 98 | X5: 634 | Y5: 551 | Z5: 452 | AA5: 18800 | AB5: 34 | AC5: 3080 | AD5: 640 | AE5: 197 | AF5: 140 | AG5: 30.7 | AH5: 17 | AI5: 17 | AJ5: 770.5 | AK5: 39 | AL5: =AJ5/AK5 -> 19.75641 | AM5: 526 | AN5: -0.12 | AO5: 1 | AP5: 0 | AQ5: 1 | AR5: 0 | AS5: 1 | AT5: =AT4 -> 20/21
A6: Liverpool | B6: 3 | C6: Liverpool | D6: 68 | E6: 42 | F6: =D6-E6 -> 26 | G6: 12 | H6: 40 | I6: 0 | J6: 67.5 | K6: 43 | L6: =D6-J6 -> 0.5 | M6: 602 | N6: 204 | O6: 6 | P6: 15 | Q6: 62 | R6: 6 | S6: 5 | T6: 65 | U6: 0 | V6: 8 | W6: 97 | X6: 563 | Y6: 526 | Z6: 396 | AA6: 21929 | AB6: 44 | AC6: 3472 | AD6: 862 | AE6: 257 | AF6: 82.65 | AG6: 17.2 | AH6: 16 | AI6: 13 | AJ6: 969.65 | AK6: 43 | AL6: =AJ6/AK6 -> 22.55 | AM6: 837 | AN6: -0.05 | AO6: 1 | AP6: 0 | AQ6: 1 | AR6: 0 | AS6: 1 | AT6: =AT5 -> 20/21
A7: Chelsea | B7: 4 | C7: Chelsea | D7: 58 | E7: 36 | F7: =D7-E7 -> 22 | G7: 18 | H7: 50 | I7: 3 | J7: 62.4 | K7: 30.3 | L7: =D7-J7 -> -4.4 | M7: 546 | N7: 193 | O7: 8 | P7: 9 | Q7: 55 | R7: 3 | S7: 2 | T7: 79 | U7: 1 | V7: 4 | W7: 71 | X7: 661 | Y7: 612 | Z7: 433 | AA7: 21969 | AB7: 29 | AC7: 3889 | AD7: 749 | AE7: 226 | AF7: 247.2 | AG7: 57.4 | AH7: 31 | AI7: 26 | AJ7: 889.2 | AK7: 39 | AL7: =AJ7/AK7 -> 22.8 | AM7: 526 | AN7: 0 | AO7: 1 | AP7: 0 | AQ7: 1 | AR7: 0 | AS7: 1 | AT7: =AT6 -> 20/21
A8: Leicester City | B8: 5 | C8: Leicester City | D8: 68 | E8: 50 | F8: =D8-E8 -> 18 | G8: 11 | H8: 61 | I8: 0 | J8: 55.8 | K8: 46 | L8: =D8-J8 -> 12.2 | M8: 473 | N8: 170 | O8: 10 | P8: 7 | Q8: 56 | R8: 3 | S8: 4 | T8: 71 | U8: 2 | V8: 4 | W8: 88 | X8: 685 | Y8: 681 | Z8: 413 | AA8: 17014 | AB8: 35 | AC8: 2955 | AD8: 649 | AE8: 212 | AF8: 59.4 | AG8: 53.77 | AH8: 19 | AI8: 18 | AJ8: 510.7 | AK8: 40 | AL8: =AJ8/AK8 -> 12.7675 | AM8: 421 | AN8: -0.1 | AO8: 1 | AP8: 0 | AQ8: 0 | AR8: 0 | AS8: 0 | AT8: =AT7 -> 20/21
A9: West Ham United | B9: 6 | C9: West Ham United | D9: 62 | E9: 47 | F9: =D9-E9 -> 15 | G9: 11 | H9: 48 | I9: 3 | J9: 55.4 | K9: 48.7 | L9: =D9-J9 -> 6.6 | M9: 464 | N9: 158 | O9: 2 | P9: 15 | Q9: 59 | R9: 3 | S9: 6 | T9: 74 | U9: 4 | V9: 5 | W9: 103 | X9: 779 | Y9: 514 | Z9: 375 | AA9: 12725 | AB9: 15 | AC9: 2230 | AD9: 775 | AE9: 167 | AF9: 54.7 | AG9: 45.41 | AH9: 16 | AI9: 17 | AJ9: 334.9 | AK9: 39 | AL9: =AJ9/AK9 -> 8.5871795 | AM9: 632 | AN9: 0.05 | AO9: 0 | AP9: 0 | AQ9: 0 | AR9: 0 | AS9: 0 | AT9: =AT8 -> 20/21
A10: Tottenham Hotspur | B10: 7 | C10: Tottenham Hotspur | D10: 68 | E10: 45 | F10: =D10-E10 -> 23 | G10: 12 | H10: 53 | I10: 2 | J10: 53.1 | K10: 49.1 | L10: =D10-J10 -> 14.9 | M10: 438 | N10: 167 | O10: 5 | P10: 10 | Q10: 58 | R10: 10 | S10: 5 | T10: 45 | U10: 3 | V10: 10 | W10: 113 | X10: 795 | Y10: 636 | Z10: 440 | AA10: 16508 | AB10: 28 | AC10: 2850 | AD10: 526 | AE10: 168 | AF10: 110.5 | AG10: 13.3 | AH10: 15 | AI10: 11 | AJ10: 703.5 | AK10: 41 | AL10: =AJ10/AK10 -> 17.158537 | AM10: 632 | AN10: 0.07 | AO10: 1 | AP10: 0 | AQ10: 0 | AR10: 0 | AS10: 1 | AT10: =AT9 -> 20/21
A11: Arsenal | B11: 8 | C11: Arsenal | D11: 55 | E11: 39 | F11: =D11-E11 -> 16 | G11: 12 | H11: 47 | I11: 5 | J11: 51.8 | K11: 43 | L11: =D11-J11 -> 3.2 | M11: 453 | N11: 140 | O11: 6 | P11: 7 | Q11: 52 | R11: 3 | S11: 1 | T11: 61 | U11: 4 | V11: 3 | W11: 93 | X11: 643 | Y11: 456 | Z11: 346 | AA11: 18041 | AB11: 34 | AC11: 3274 | AD11: 751 | AE11: 207 | AF11: 86 | AG11: 19.15 | AH11: 16 | AI11: 16 | AJ11: 619.25 | AK11: 42 | AL11: =AJ11/AK11 -> 14.744048 | AM11: 632 | AN11: -0.11 | AO11: 1 | AP11: 0 | AQ11: 0 | AR11: 0 | AS11: 1 | AT11: =AT10 -> 20/21
A12: Leeds United | B12: 9 | C12: Leeds United | D12: 62 | E12: 54 | F12: =D12-E12 -> 8 | G12: 12 | H12: 61 | I12: 1 | J12: 55.6 | K12: 57.9 | L12: =D12-J12 -> 6.4 | M12: 518 | N12: 193 | O12: 4 | P12: 9 | Q12: 48 | R12: 14 | S12: 7 | T12: 76 | U12: 2 | V12: 9 | W12: 145 | X12: 646 | Y12: 740 | Z12: 432 | AA12: 16284 | AB12: 27 | AC12: 2666 | AD12: 786 | AE12: 229 | AF12: 106.8 | AG12: 0 | AH12: 16 | AI12: 17 | AJ12: 238.1 | AK12: 39 | AL12: =AJ12/AK12 -> 6.1051282 | AM12: 421 | AN12: 0.06 | AO12: 0 | AP12: 1 | AQ12: 0 | AR12: 0 | AS12: 0 | AT12: =AT11 -> 20/21
A13: Everton | B13: 10 | C13: Everton | D13: 47 | E13: 48 | F13: =D13-E13 -> -1 | G13: 12 | H13: 59 | I13: 2 | J13: 45.7 | K13: 50.1 | L13: =D13-J13 -> 1.3 | M13: 395 | N13: 143 | O13: 4 | P13: 15 | Q13: 44 | R13: 3 | S13: 0 | T13: 65 | U13: 1 | V13: 4 | W13: 114 | X13: 847 | Y13: 640 | Z13: 386 | AA13: 14792 | AB13: 28 | AC13: 2693 | AD13: 662 | AE13: 167 | AF13: 73.37 | AG13: 4.43 | AH13: 20 | AI13: 20 | AJ13: 511.2 | AK13: 44 | AL13: =AJ13/AK13 -> 11.618182 | AM13: 368 | AN13: -0.08 | AO13: 0 | AP13: 0 | AQ13: 0 | AR13: 0 | AS13: 0 | AT13: =AT12 -> 20/21
A14: Aston Villa | B14: 11 | C14: Aston Villa | D14: 55 | E14: 46 | F14: =D14-E14 -> 9 | G14: 15 | H14: 63 | I14: 4 | J14: 52.5 | K14: 51.1 | L14: =D14-J14 -> 2.5 | M14: 514 | N14: 178 | O14: 5 | P14: 7 | Q14: 47 | R14: 8 | S14: 4 | T14: 71 | U14: 1 | V14: 6 | W14: 133 | X14: 783 | Y14: 530 | Z14: 439 | AA14: 12938 | AB14: 12 | AC14: 2308 | AD14: 779 | AE14: 213 | AF14: 101.35 | AG14: 2.77 | AH14: 12 | AI14: 15 | AJ14: 430.75 | AK14: 53 | AL14: =AJ14/AK14 -> 8.1273585 | AM14: 526 | AN14: -0.06 | AO14: 0 | AP14: 0 | AQ14: 0 | AR14: 0 | AS14: 0 | AT14: =AT13 -> 20/21
A15: Newcastle United | B15: 12 | C15: Newcastle United | D15: 46 | E15: 62 | F15: =D15-E15 -> -16 | G15: 7 | H15: 61 | I15: 3 | J15: 43.4 | K15: 58.3 | L15: =D15-J15 -> 2.6 | M15: 390 | N15: 130 | O15: 6 | P15: 9 | Q15: 43 | R15: 3 | S15: 3 | T15: 58 | U15: 3 | V15: 5 | W15: 128 | X15: 908 | Y15: 512 | Z15: 388 | AA15: 10839 | AB15: 12 | AC15: 2088 | AD15: 652 | AE15: 161 | AF15: 39 | AG15: 0.275 | AH15: 11 | AI15: 15 | AJ15: 255.75 | AK15: 33 | AL15: =AJ15/AK15 -> 7.75 | AM15: 526 | AN15: 0.03 | AO15: 0 | AP15: 0 | AQ15: 0 | AR15: 0 | AS15: 0 | AT15: =AT14 -> 20/21
A16: Wolverhampton Wanderers | B16: 13 | C16: Wolverhampton Wanderers | D16: 36 | E16: 52 | F16: =D16-E16 -> -16 | G16: 10 | H16: 53 | I16: 1 | J16: 36.5 | K16: 49.5 | L16: =D16-J16 -> -0.5 | M16: 459 | N16: 149 | O16: 4 | P16: 8 | Q16: 34 | R16: 3 | S16: 2 | T16: 37 | U16: 3 | V16: 8 | W16: 102 | X16: 727 | Y16: 588 | Z16: 426 | AA16: 15548 | AB16: 20 | AC16: 2943 | AD16: 775 | AE16: 208 | AF16: 87.8 | AG16: 79.2 | AH16: 21 | AI16: 24 | AJ16: 450.3 | AK16: 38 | AL16: =AJ16/AK16 -> 11.85 | AM16: 237 | AN16: 0.11 | AO16: 0 | AP16: 0 | AQ16: 0 | AR16: 0 | AS16: 0 | AT16: =AT15 -> 20/21
... A23: Sheffield Utd | B23: 20 | C23: Sheffield United | D23: 20 | E23: 63 | F23: =D23-E23 -> -43 | G23: 5 | H23: 73 | I23: 3 | J23: 32.6 | K23: 62.2 | L23: =D23-J23 -> -12.6 | M23: 319 | N23: 92 | O23: 3 | P23: 4 | Q23: 18 | R23: 2 | S23: 0 | T23: 73 | U23: 3 | V23: 4 | W23: 145 | X23: 839 | Y23: 634 | Z23: 459 | AA23: 12146 | AB23: 13 | AC23: 2405 | AD23: 666 | AE23: 170 | AF23: 62.7 | AG23: 0 | AH23: 16 | AI23: 19 | AJ23: 149.85 | AK23: 40 | AL23: =AJ23/AK23 -> 3.74625 | AM23: 263 | AN23: 0.17 | AO23: 0 | AP23: 0 | AQ23: 0 | AR23: 1 | AS23: 0 | AT23: =AT22 -> 20/21

Sheet 2021-2022
B2: Temporada 2021/2022 | D2: General | M2: Ataque | U2: Defensa | AA2: Tipo de juego | AF2: Extra cancha
B3: Posición en la tabla | C3: Equipo | D3: Goles a favor | E3: Goles en contra | F3: Diferencia de goles | G3: Porterias en cero | H3: Tarjetas Amarillas | I3: Tarjetas Rojas | J3: XG F | K3: XG A | L3: G vs XG | M3: Tiros | N3: Tiros a gol | O3: Gol de penal | P3: Gol de cabeza | Q3: Gol dentro del área | R3: Gol fuera del área | S3: Gol de contragolpe | T3: Fueras de lugar | U3: Auotgoles | V3: Penales provocados | W3: Paradas | X3: Despejes | Y3: Barridas | Z3: Faltas | AA3: # de pases | AB3: Pases filtrados | AC3: Pases hacia atrás | AD3: Centros | AE3: Corners | AF3: Dinero gastado en transferencias (Millones de euros) | AG3: Dinero ingresado por transferencias (millones de euros) | AH3: Jugadores nuevos | AI3: Jugadores vendidos | AJ3: Valor de la plantilla | AK3: # de jugadores | AL3: Valor promedio jugadores | AM3: Asistencia promedio al estadio | AN3: % ventaja local | AO3: Competencias Europeas | AP3: Recien ascendido | AQ3: Champions | AR3: Descenso | AS3: Big 6 | AT3: Temporada
B4: 1 | C4: Manchester City | D4: 99 | E4: 26 | F4: 73 | G4: 21 | H4: 42 | I4: 1 | J4: 88.7 | K4: 24.6 | L4: 10.3 | M4: 704 | N4: 237 | O4: 7 | P4: 15 | Q4: 84 | R4: 15 | S4: 2 | T4: 66 | U4: 0 | V4: 1 | W4: 59 | X4: 227 | Y4: 403 | Z4: 321 | AA4: 24406 | AB4: 102 | AC4: 4426 | AD4: 869 | AE4: 316 | AF4: 138.9 | AG4: 93.8 | AH4: 21 | AI4: 24 | AJ4: 1000 | AK4: 39 | AL4: 25.641026 | AM4: 52774 | AN4: 0.01 | AO4: 1 | AP4: 0 | AQ4: 1 | AR4: 0 | AS4: 1 | AT4: 21/22
B5: 2 | C5: Liverpool | D5: 94 | E5: 26 | F5: 68 | G5: 21 | H5: 50 | I5: 1 | J5: 88.7 | K5: 33.8 | L5: 5.3 | M5: 721 | N5: 237 | O5: 7 | P5: 16 | Q5: 86 | R5: 8 | S5: 5 | T5: 63 | U5: 1 | V5: 0 | W5: 82 | X5: 523 | Y5: 523 | Z5: 363 | AA5: 21163 | AB5: 112 | AC5: 3505 | AD5: 897 | AE5: 282 | AF5: 87 | AG5: 29.55 | AH5: 14 | AI5: 12 | AJ5: 918.9 | AK5: 49 | AL5: 18.753061 | AM5: 53352 | AN5: 0.18 | AO5: 1 | AP5: 0 | AQ5: 1 | AR5: 0 | AS5: 1 | AT5: 21/22
B6: 3 | C6: Chelsea | D6: 76 | E6: 33 | F6: 43 | G6: 16 | H6: 63 | I6: 1 | J6: 63.4 | K6: 33.2 | L6: 12.6 | M6: 583 | N6: 200 | O6: 8 | P6: 12 | Q6: 63 | R6: 14 | S6: 0 | T6: 69 | U6: 1 | V6: 6 | W6: 83 | X6: 641 | Y6: 641 | Z6: 409 | AA6: 21190 | AB6: 77 | AC6: 3698 | AD6: 745 | AE6: 241 | AF6: 118 | AG6: 148.9 | AH6: 21 | AI6: 23 | AJ6: 914.5 | AK6: 44 | AL6: 20.784091 | AM6: 36443 | AN6: -0.18 | AO6: 1 | AP6: 0 | AQ6: 1 | AR6: 0 | AS6: 1 | AT6: 21/22
B7: 4 | C7: Tottenham Hotspur | D7: 69 | E7: 40 | F7: 29 | G7: 16 | H7: 69 | I7: 1 | J7: 61.2 | K7: 39.3 | L7: 7.8 | M7: 486 | N7: 185 | O7: 5 | P7: 8 | Q7: 62 | R7: 8 | S7: 4 | T7: 62 | U7: 1 | V7: 2 | W7: 98 | X7: 793 | Y7: 793 | Z7: 386 | AA7: 17204 | AB7: 88 | AC7: 2825 | AD7: 632 | AE7: 193 | AF7: 95.9 | AG7: 34.62 | AH7: 14 | AI7: 19 | AJ7: 689.35 | AK7: 45 | AL7: 15.318889 | AM7: 56523 | AN7: 0.08 | AO7: 1 | AP7: 0 | AQ7: 1 | AR7: 0 | AS7: 1 | AT7: 21/22
B8: 5 | C8: Arsenal | D8: 61 | E8: 48 | F8: 13 | G8: 13 | H8: 67 | I8: 4 | J8: 60.5 | K8: 45.7 | L8: 0.5 | M8: 581 | N8: 186 | O8: 5 | P8: 9 | Q8: 52 | R8: 10 | S8: 6 | T8: 66 | U8: 1 | V8: 6 | W8: 100 | X8: 658 | Y8: 658 | Z8: 365 | AA8: 16176 | AB8: 77 | AC8: 2876 | AD8: 633 | AE8: 208 | AF8: 167.42 | AG8: 31.4 | AH8: 13 | AI8: 20 | AJ8: 613.05 | AK8: 41 | AL8: 14.952439 | AM8: 59665 | AN8: 0.22 | AO8: 0 | AP8: 0 | AQ8: 0 | AR8: 0 | AS8: 1 | AT8: 21/22
B9: 6 | C9: Manchester United | D9: 57 | E9: 57 | F9: 0 | G9: 8 | H9: 77 | I9: 2 | J9: 55.8 | K9: 53 | L9: 1.2 | M9: 503 | N9: 179 | O9: 3 | P9: 7 | Q9: 49 | R9: 8 | S9: 0 | T9: 88 | U9: 3 | V9: 5 | W9: 124 | X9: 704 | Y9: 704 | Z9: 396 | AA9: 16690 | AB9: 80 | AC9: 2810 | AD9: 659 | AE9: 197 | AF9: 142 | AG9: 31.1 | AH9: 17 | AI9: 14 | AJ9: 769.15 | AK9: 43 | AL9: 17.887209 | AM9: 73150 | AN9: 0.18 | AO9: 1 | AP9: 0 | AQ9: 0 | AR9: 0 | AS9: 1 | AT9: 21/22
B10: 7 | C10: West Ham United | D10: 60 | E10: 51 | F10: 9 | G10: 8 | H10: 52 | I10: 3 | J10: 51.4 | K10: 53.5 | L10: 8.6 | M10: 443 | N10: 142 | O10: 4 | P10: 8 | Q10: 52 | R10: 9 | S10: 6 | T10: 59 | U10: 2 | V10: 6 | W10: 113 | X10: 781 | Y10: 781 | Z10: 323 | AA10: 14326 | AB10: 29 | AC10: 2533 | AD10: 802 | AE10: 200 | AF10: 74.5 | AG10: 4.24 | AH10: 10 | AI10: 8 | AJ10: 354.9 | AK10: 36 | AL10: 9.8583333 | AM10: 58370 | AN10: 0.04 | AO10: 1 | AP10: 0 | AQ10: 0 | AR10: 0 | AS10: 0 | AT10: 21/22
B11: 8 | C11: Leicester City | D11: 62 | E11: 59 | F11: 3 | G11: 7 | H11: 55 | I11: 1 | J11: 47.8 | K11: 59.3 | L11: 14.2 | M11: 433 | N11: 164 | O11: 2 | P11: 5 | Q11: 55 | R11: 7 | S11: 4 | T11: 60 | U11: 1 | V11: 9 | W11: 132 | X11: 777 | Y11: 777 | Z11: 356 | AA11: 16129 | AB11: 65 | AC11: 2765 | AD11: 556 | AE11: 185 | AF11: 67.6 | AG11: 4 | AH11: 11 | AI11: 11 | AJ11: 526.55 | AK11: 40 | AL11: 13.16375 | AM11: 32493 | AN11: 0.16 | AO11: 1 | AP11: 0 | AQ11: 0 | AR11: 0 | AS11: 0 | AT11: 21/22
B12: 9 | C12: Brighton and Hove Albion | D12: 42 | E12: 44 | F12: -2 | G12: 11 | H12: 72 | I12: 2 | J12: 46.2 | K12: 42.9 | L12: -4.2 | M12: 482 | N12: 141 | O12: 4 | P12: 8 | Q12: 34 | R12: 8 | S12: 2 | T12: 53 | U12: 0 | V12: 4 | W12: 102 | X12: 723 | Y12: 723 | Z12: 393 | AA12: 16410 | AB12: 58 | AC12: 3069 | AD12: 728 | AE12: 200 | AF12: 75 | AG12: 78.8 | AH12: 26 | AI12: 29 | AJ12: 318 | AK12: 43 | AL12: 7.3953488 | AM12: 30966 | AN12: -0.07 | AO12: 0 | AP12: 0 | AQ12: 0 | AR12: 0 | AS12: 0 | AT12: 21/22
B13: 10 | C13: Wolverhampton Wanderers | D13: 38 | E13: 43 | F13: -5 | G13: 11 | H13: 62 | I13: 2 | J13: 37.5 | K13: 56.9 | L13: 0.5 | M13: 401 | N13: 133 | O13: 1 | P13: 5 | Q13: 30 | R13: 8 | S13: 4 | T13: 61 | U13: 1 | V13: 10 | W13: 125 | X13: 820 | Y13: 820 | Z13: 366 | AA13: 15253 | AB13: 58 | AC13: 2665 | AD13: 587 | AE13: 168 | AF13: 37.6 | AG13: 31.8 | AH13: 26 | AI13: 22 | AJ13: 376.95 | AK13: 38 | AL13: 9.9197368 | AM13: 30841 | AN13: -0.06 | AO13: 0 | AP13: 0 | AQ13: 0 | AR13: 0 | AS13: 0 | AT13: 21/22
B14: 11 | C14: Newcastle United | D14: 44 | E14: 62 | F14: -18 | G14: 8 | H14: 81 | I14: 2 | J14: 38.1 | K14: 57.1 | L14: 5.9 | M14: 446 | N14: 142 | O14: 3 | P14: 9 | Q14: 37 | R14: 7 | S14: 3 | T14: 71 | U14: 2 | V14: 6 | W14: 104 | X14: 776 | Y14: 776 | Z14: 392 | AA14: 10201 | AB14: 31 | AC14: 1869 | AD14: 592 | AE14: 160 | AF14: 130.5 | AG14: 0 | AH14: 13 | AI14: 11 | AJ14: 313.9 | AK14: 34 | AL14: 9.2323529 | AM14: 51487 | AN14: 0.16 | AO14: 0 | AP14: 0 | AQ14: 0 | AR14: 0 | AS14: 0 | AT14: 21/22
B15: 12 | C15: Crystal Palace | D15: 50 | E15: 46 | F15: 4 | G15: 12 | H15: 69 | I15: 1 | J15: 46.4 | K15: 40.7 | L15: 3.6 | M15: 404 | N15: 140 | O15: 6 | P15: 6 | Q15: 45 | R15: 5 | S15: 2 | T15: 63 | U15: 2 | V15: 4 | W15: 99 | X15: 761 | Y15: 761 | Z15: 414 | AA15: 14983 | AB15: 40 | AC15: 2829 | AD15: 643 | AE15: 175 | AF15: 85.62 | AG15: 0 | AH15: 13 | AI15: 16 | AJ15: 271.05 | AK15: 33 | AL15: 8.2136364 | AM15: 24588 | AN15: 0.17 | AO15: 0 | AP15: 0 | AQ15: 0 | AR15: 0 | AS15: 0 | AT15: 21/22
... B23: 20 | C23: Norwich City | D23: 23 | E23: 84 | F23: -61 | G23: 6 | H23: 57 | I23: 1 | J23: 32.3 | K23: 75.5 | L23: -9.3 | M23: 370 | N23: 104 | O23: 3 | P23: 5 | Q23: 20 | R23: 3 | S23: 1 | T23: 55 | U23: 2 | V23: 12 | W23: 139 | X23: 860 | Y23: 860 | Z23: 356 | AA23: 12164 | AB23: 50 | AC23: 2289 | AD23: 568 | AE23: 165 | AF23: 63.55 | AG23: 38.4 | AH23: 32 | AI23: 31 | AJ23: 163.2 | AK23: 45 | AL23: 3.6266667 | AM23: 26836 | AN23: 0.01 | AO23: 0 | AP23: 1 | AQ23: 0 | AR23: 1 | AS23: 0 | AT23: 21/22

Sheet 2022-2023
B2: Temporada 2022/2023 | D2: General | M2: Ataque | U2: Defensa | AA2: Tipo de juego | AF2: Extra cancha
B3: Posición en la tabla | C3: Equipo | D3: Goles a favor | E3: Goles en contra | F3: Diferencia de goles | G3: Porterias en cero | H3: Tarjetas Amarillas | I3: Tarjetas Rojas | J3: XG F | K3: XG A | L3: G vs XG | M3: Tiros | N3: Tiros a gol | O3: Gol de penal | P3: Gol de cabeza | Q3: Gol dentro del área | R3: Gol fuera del área | S3: Gol de contragolpe | T3: Fueras de lugar | U3: Auotgoles | V3: Penales provocados | W3: Paradas | X3: Despejes | Y3: Barridas | Z3: Faltas | AA3: # de pases | AB3: Pases filtrados | AC3: Pases hacia atrás | AD3: Centros | AE3: Corners | AF3: Dinero gastado en transferencias (Millones de euros) | AG3: Dinero ingresado por transferencias (millones de euros) | AH3: Jugadores nuevos | AI3: Jugadores vendidos | AJ3: Valor de la plantilla | AK3: # de jugadores | AL3: Valor promedio jugadores | AM3: Asistencia promedio al estadio | AN3: % ventaja local | AO3: Competencias Europeas | AP3: Recien ascendido | AQ3: Champions | AR3: Descenso | AS3: Big 6 | AT3: Temporada
B4: 1 | C4: Manchester City | D4: 94 | E4: 33 | F4: 61 | G4: 13 | H4: 44 | I4: 1 | J4: 78.7 | K4: 32.1 | L4: 15.3 | M4: 590 | N4: 205 | O4: 9 | P4: 12 | Q4: 82 | R4: 13 | S4: 7 | T4: 51 | U4: 1 | V4: 3 | W4: 60 | X4: 391 | Y4: 272 | Z4: 347 | AA4: 25072 | AB4: 94 | AC4: 4236 | AD4: 742 | AE4: 238 | AF4: 155 | AG4: 162.17 | AH4: 29 | AI4: 24 | AJ4: 1150 | AK4: 34 | AL4: =AJ4/AK4 -> 33.823529 | AM4: 53249 | AN4: 0.13 | AO4: 1 | AP4: 0 | AQ4: 1 | AR4: 0 | AS4: 1 | AT4: 22/23
